Traceback (most recent call last):
  File "/root/GPT_monitoring/webhook_server.py", line 1, in <module>
    from future import annotations
ImportError: cannot import name 'annotations' from 'future' (/root/GPT_monitoring/.venv/lib/python3.12/site-packages/future/__init__.py)
Traceback (most recent call last):
  File "/root/GPT_monitoring/webhook_server.py", line 1, in <module>
    from future import annotations
ImportError: cannot import name 'annotations' from 'future' (/root/GPT_monitoring/.venv/lib/python3.12/site-packages/future/__init__.py)
Traceback (most recent call last):
  File "/root/GPT_monitoring/webhook_server.py", line 1, in <module>
    from future import annotations
ImportError: cannot import name 'annotations' from 'future' (/root/GPT_monitoring/.venv/lib/python3.12/site-packages/future/__init__.py)
Traceback (most recent call last):
  File "/root/GPT_monitoring/webhook_server.py", line 1, in <module>
    from future import annotations
ImportError: cannot import name 'annotations' from 'future' (/root/GPT_monitoring/.venv/lib/python3.12/site-packages/future/__init__.py)
Traceback (most recent call last):
  File "/root/GPT_monitoring/webhook_server.py", line 1, in <module>
    from future import annotations
ImportError: cannot import name 'annotations' from 'future' (/root/GPT_monitoring/.venv/lib/python3.12/site-packages/future/__init__.py)
Traceback (most recent call last):
  File "/root/GPT_monitoring/webhook_server.py", line 1, in <module>
    from future import annotations
ImportError: cannot import name 'annotations' from 'future' (/root/GPT_monitoring/.venv/lib/python3.12/site-packages/future/__init__.py)
Traceback (most recent call last):
  File "/root/GPT_monitoring/webhook_server.py", line 1, in <module>
    from future import annotations
ImportError: cannot import name 'annotations' from 'future' (/root/GPT_monitoring/.venv/lib/python3.12/site-packages/future/__init__.py)
Traceback (most recent call last):
  File "/root/GPT_monitoring/webhook_server.py", line 1, in <module>
    from future import annotations
ImportError: cannot import name 'annotations' from 'future' (/root/GPT_monitoring/.venv/lib/python3.12/site-packages/future/__init__.py)
Traceback (most recent call last):
  File "/root/GPT_monitoring/webhook_server.py", line 1, in <module>
    from future import annotations
ImportError: cannot import name 'annotations' from 'future' (/root/GPT_monitoring/.venv/lib/python3.12/site-packages/future/__init__.py)
Traceback (most recent call last):
  File "/root/GPT_monitoring/webhook_server.py", line 1, in <module>
    from future import annotations
ImportError: cannot import name 'annotations' from 'future' (/root/GPT_monitoring/.venv/lib/python3.12/site-packages/future/__init__.py)
Traceback (most recent call last):
  File "/root/GPT_monitoring/webhook_server.py", line 1, in <module>
    from future import annotations
ImportError: cannot import name 'annotations' from 'future' (/root/GPT_monitoring/.venv/lib/python3.12/site-packages/future/__init__.py)
Traceback (most recent call last):
  File "/root/GPT_monitoring/webhook_server.py", line 1, in <module>
    from future import annotations
ImportError: cannot import name 'annotations' from 'future' (/root/GPT_monitoring/.venv/lib/python3.12/site-packages/future/__init__.py)
Traceback (most recent call last):
  File "/root/GPT_monitoring/webhook_server.py", line 1, in <module>
    from future import annotations
ImportError: cannot import name 'annotations' from 'future' (/root/GPT_monitoring/.venv/lib/python3.12/site-packages/future/__init__.py)
Traceback (most recent call last):
  File "/root/GPT_monitoring/webhook_server.py", line 1, in <module>
    from future import annotations
ImportError: cannot import name 'annotations' from 'future' (/root/GPT_monitoring/.venv/lib/python3.12/site-packages/future/__init__.py)
Traceback (most recent call last):
  File "/root/GPT_monitoring/webhook_server.py", line 1, in <module>
    from future import annotations
ImportError: cannot import name 'annotations' from 'future' (/root/GPT_monitoring/.venv/lib/python3.12/site-packages/future/__init__.py)
Traceback (most recent call last):
  File "/root/GPT_monitoring/webhook_server.py", line 1, in <module>
    from future import annotations
ImportError: cannot import name 'annotations' from 'future' (/root/GPT_monitoring/.venv/lib/python3.12/site-packages/future/__init__.py)
Traceback (most recent call last):
  File "/root/GPT_monitoring/webhook_server.py", line 1, in <module>
    from future import annotations
ImportError: cannot import name 'annotations' from 'future' (/root/GPT_monitoring/.venv/lib/python3.12/site-packages/future/__init__.py)
Traceback (most recent call last):
  File "/root/GPT_monitoring/webhook_server.py", line 1, in <module>
    from future import annotations
ImportError: cannot import name 'annotations' from 'future' (/root/GPT_monitoring/.venv/lib/python3.12/site-packages/future/__init__.py)
Traceback (most recent call last):
  File "/root/GPT_monitoring/webhook_server.py", line 1, in <module>
    from future import annotations
ImportError: cannot import name 'annotations' from 'future' (/root/GPT_monitoring/.venv/lib/python3.12/site-packages/future/__init__.py)
Traceback (most recent call last):
  File "/root/GPT_monitoring/webhook_server.py", line 1, in <module>
    from future import annotations
ImportError: cannot import name 'annotations' from 'future' (/root/GPT_monitoring/.venv/lib/python3.12/site-packages/future/__init__.py)
Traceback (most recent call last):
  File "/root/GPT_monitoring/webhook_server.py", line 1, in <module>
    from future import annotations
ImportError: cannot import name 'annotations' from 'future' (/root/GPT_monitoring/.venv/lib/python3.12/site-packages/future/__init__.py)
Traceback (most recent call last):
  File "/root/GPT_monitoring/webhook_server.py", line 1, in <module>
    from future import annotations
ImportError: cannot import name 'annotations' from 'future' (/root/GPT_monitoring/.venv/lib/python3.12/site-packages/future/__init__.py)
Traceback (most recent call last):
  File "/root/GPT_monitoring/webhook_server.py", line 1, in <module>
    from future import annotations
ImportError: cannot import name 'annotations' from 'future' (/root/GPT_monitoring/.venv/lib/python3.12/site-packages/future/__init__.py)
Traceback (most recent call last):
  File "/root/GPT_monitoring/webhook_server.py", line 1, in <module>
    from future import annotations
ImportError: cannot import name 'annotations' from 'future' (/root/GPT_monitoring/.venv/lib/python3.12/site-packages/future/__init__.py)
Traceback (most recent call last):
  File "/root/GPT_monitoring/webhook_server.py", line 1, in <module>
    from future import annotations
ImportError: cannot import name 'annotations' from 'future' (/root/GPT_monitoring/.venv/lib/python3.12/site-packages/future/__init__.py)
Traceback (most recent call last):
  File "/root/GPT_monitoring/webhook_server.py", line 1, in <module>
    from future import annotations
ImportError: cannot import name 'annotations' from 'future' (/root/GPT_monitoring/.venv/lib/python3.12/site-packages/future/__init__.py)
Traceback (most recent call last):
  File "/root/GPT_monitoring/webhook_server.py", line 1, in <module>
    from future import annotations
ImportError: cannot import name 'annotations' from 'future' (/root/GPT_monitoring/.venv/lib/python3.12/site-packages/future/__init__.py)
Traceback (most recent call last):
  File "/root/GPT_monitoring/webhook_server.py", line 1, in <module>
    from future import annotations
ImportError: cannot import name 'annotations' from 'future' (/root/GPT_monitoring/.venv/lib/python3.12/site-packages/future/__init__.py)
Traceback (most recent call last):
  File "/root/GPT_monitoring/webhook_server.py", line 1, in <module>
    from future import annotations
ImportError: cannot import name 'annotations' from 'future' (/root/GPT_monitoring/.venv/lib/python3.12/site-packages/future/__init__.py)
Traceback (most recent call last):
  File "/root/GPT_monitoring/webhook_server.py", line 1, in <module>
    from future import annotations
ImportError: cannot import name 'annotations' from 'future' (/root/GPT_monitoring/.venv/lib/python3.12/site-packages/future/__init__.py)
Traceback (most recent call last):
  File "/root/GPT_monitoring/webhook_server.py", line 1, in <module>
    from future import annotations
ImportError: cannot import name 'annotations' from 'future' (/root/GPT_monitoring/.venv/lib/python3.12/site-packages/future/__init__.py)
Traceback (most recent call last):
  File "/root/GPT_monitoring/webhook_server.py", line 1, in <module>
    from future import annotations
ImportError: cannot import name 'annotations' from 'future' (/root/GPT_monitoring/.venv/lib/python3.12/site-packages/future/__init__.py)
Traceback (most recent call last):
  File "/root/GPT_monitoring/webhook_server.py", line 1, in <module>
    from future import annotations
ImportError: cannot import name 'annotations' from 'future' (/root/GPT_monitoring/.venv/lib/python3.12/site-packages/future/__init__.py)
Traceback (most recent call last):
  File "/root/GPT_monitoring/webhook_server.py", line 1, in <module>
    from future import annotations
ImportError: cannot import name 'annotations' from 'future' (/root/GPT_monitoring/.venv/lib/python3.12/site-packages/future/__init__.py)
Traceback (most recent call last):
  File "/root/GPT_monitoring/webhook_server.py", line 1, in <module>
    from future import annotations
ImportError: cannot import name 'annotations' from 'future' (/root/GPT_monitoring/.venv/lib/python3.12/site-packages/future/__init__.py)
Traceback (most recent call last):
  File "/root/GPT_monitoring/webhook_server.py", line 1, in <module>
    from future import annotations
ImportError: cannot import name 'annotations' from 'future' (/root/GPT_monitoring/.venv/lib/python3.12/site-packages/future/__init__.py)
Traceback (most recent call last):
  File "/root/GPT_monitoring/webhook_server.py", line 1, in <module>
    from future import annotations
ImportError: cannot import name 'annotations' from 'future' (/root/GPT_monitoring/.venv/lib/python3.12/site-packages/future/__init__.py)
Traceback (most recent call last):
  File "/root/GPT_monitoring/webhook_server.py", line 1, in <module>
    from future import annotations
ImportError: cannot import name 'annotations' from 'future' (/root/GPT_monitoring/.venv/lib/python3.12/site-packages/future/__init__.py)
Traceback (most recent call last):
  File "/root/GPT_monitoring/webhook_server.py", line 1, in <module>
    from future import annotations
ImportError: cannot import name 'annotations' from 'future' (/root/GPT_monitoring/.venv/lib/python3.12/site-packages/future/__init__.py)
Traceback (most recent call last):
  File "/root/GPT_monitoring/webhook_server.py", line 1, in <module>
    from future import annotations
ImportError: cannot import name 'annotations' from 'future' (/root/GPT_monitoring/.venv/lib/python3.12/site-packages/future/__init__.py)
Traceback (most recent call last):
  File "/root/GPT_monitoring/webhook_server.py", line 1, in <module>
    from future import annotations
ImportError: cannot import name 'annotations' from 'future' (/root/GPT_monitoring/.venv/lib/python3.12/site-packages/future/__init__.py)
Traceback (most recent call last):
  File "/root/GPT_monitoring/webhook_server.py", line 1, in <module>
    from future import annotations
ImportError: cannot import name 'annotations' from 'future' (/root/GPT_monitoring/.venv/lib/python3.12/site-packages/future/__init__.py)
Traceback (most recent call last):
  File "/root/GPT_monitoring/webhook_server.py", line 1, in <module>
    from future import annotations
ImportError: cannot import name 'annotations' from 'future' (/root/GPT_monitoring/.venv/lib/python3.12/site-packages/future/__init__.py)
Traceback (most recent call last):
  File "/root/GPT_monitoring/webhook_server.py", line 1, in <module>
    from future import annotations
ImportError: cannot import name 'annotations' from 'future' (/root/GPT_monitoring/.venv/lib/python3.12/site-packages/future/__init__.py)
Traceback (most recent call last):
  File "/root/GPT_monitoring/webhook_server.py", line 1, in <module>
    from future import annotations
ImportError: cannot import name 'annotations' from 'future' (/root/GPT_monitoring/.venv/lib/python3.12/site-packages/future/__init__.py)
Traceback (most recent call last):
  File "/root/GPT_monitoring/webhook_server.py", line 1, in <module>
    from future import annotations
ImportError: cannot import name 'annotations' from 'future' (/root/GPT_monitoring/.venv/lib/python3.12/site-packages/future/__init__.py)
Traceback (most recent call last):
  File "/root/GPT_monitoring/webhook_server.py", line 1, in <module>
    from future import annotations
ImportError: cannot import name 'annotations' from 'future' (/root/GPT_monitoring/.venv/lib/python3.12/site-packages/future/__init__.py)
Traceback (most recent call last):
  File "/root/GPT_monitoring/webhook_server.py", line 1, in <module>
    from future import annotations
ImportError: cannot import name 'annotations' from 'future' (/root/GPT_monitoring/.venv/lib/python3.12/site-packages/future/__init__.py)
Traceback (most recent call last):
  File "/root/GPT_monitoring/webhook_server.py", line 1, in <module>
    from future import annotations
ImportError: cannot import name 'annotations' from 'future' (/root/GPT_monitoring/.venv/lib/python3.12/site-packages/future/__init__.py)
Traceback (most recent call last):
  File "/root/GPT_monitoring/webhook_server.py", line 1, in <module>
    from future import annotations
ImportError: cannot import name 'annotations' from 'future' (/root/GPT_monitoring/.venv/lib/python3.12/site-packages/future/__init__.py)
Traceback (most recent call last):
  File "/root/GPT_monitoring/webhook_server.py", line 1, in <module>
    from future import annotations
ImportError: cannot import name 'annotations' from 'future' (/root/GPT_monitoring/.venv/lib/python3.12/site-packages/future/__init__.py)
Traceback (most recent call last):
  File "/root/GPT_monitoring/webhook_server.py", line 1, in <module>
    from future import annotations
ImportError: cannot import name 'annotations' from 'future' (/root/GPT_monitoring/.venv/lib/python3.12/site-packages/future/__init__.py)
Traceback (most recent call last):
  File "/root/GPT_monitoring/webhook_server.py", line 1, in <module>
    from future import annotations
ImportError: cannot import name 'annotations' from 'future' (/root/GPT_monitoring/.venv/lib/python3.12/site-packages/future/__init__.py)
Traceback (most recent call last):
  File "/root/GPT_monitoring/webhook_server.py", line 1, in <module>
    from future import annotations
ImportError: cannot import name 'annotations' from 'future' (/root/GPT_monitoring/.venv/lib/python3.12/site-packages/future/__init__.py)
Traceback (most recent call last):
  File "/root/GPT_monitoring/webhook_server.py", line 1, in <module>
    from future import annotations
ImportError: cannot import name 'annotations' from 'future' (/root/GPT_monitoring/.venv/lib/python3.12/site-packages/future/__init__.py)
Traceback (most recent call last):
  File "/root/GPT_monitoring/webhook_server.py", line 1, in <module>
    from future import annotations
ImportError: cannot import name 'annotations' from 'future' (/root/GPT_monitoring/.venv/lib/python3.12/site-packages/future/__init__.py)
Traceback (most recent call last):
  File "/root/GPT_monitoring/webhook_server.py", line 1, in <module>
    from future import annotations
ImportError: cannot import name 'annotations' from 'future' (/root/GPT_monitoring/.venv/lib/python3.12/site-packages/future/__init__.py)
Traceback (most recent call last):
  File "/root/GPT_monitoring/webhook_server.py", line 1, in <module>
    from future import annotations
ImportError: cannot import name 'annotations' from 'future' (/root/GPT_monitoring/.venv/lib/python3.12/site-packages/future/__init__.py)
Traceback (most recent call last):
  File "/root/GPT_monitoring/webhook_server.py", line 1, in <module>
    from future import annotations
ImportError: cannot import name 'annotations' from 'future' (/root/GPT_monitoring/.venv/lib/python3.12/site-packages/future/__init__.py)
Traceback (most recent call last):
  File "/root/GPT_monitoring/webhook_server.py", line 1, in <module>
    from future import annotations
ImportError: cannot import name 'annotations' from 'future' (/root/GPT_monitoring/.venv/lib/python3.12/site-packages/future/__init__.py)
Traceback (most recent call last):
  File "/root/GPT_monitoring/webhook_server.py", line 1, in <module>
    from future import annotations
ImportError: cannot import name 'annotations' from 'future' (/root/GPT_monitoring/.venv/lib/python3.12/site-packages/future/__init__.py)
Traceback (most recent call last):
  File "/root/GPT_monitoring/webhook_server.py", line 1, in <module>
    from future import annotations
ImportError: cannot import name 'annotations' from 'future' (/root/GPT_monitoring/.venv/lib/python3.12/site-packages/future/__init__.py)
Traceback (most recent call last):
  File "/root/GPT_monitoring/webhook_server.py", line 1, in <module>
    from future import annotations
ImportError: cannot import name 'annotations' from 'future' (/root/GPT_monitoring/.venv/lib/python3.12/site-packages/future/__init__.py)
Traceback (most recent call last):
  File "/root/GPT_monitoring/webhook_server.py", line 1, in <module>
    from future import annotations
ImportError: cannot import name 'annotations' from 'future' (/root/GPT_monitoring/.venv/lib/python3.12/site-packages/future/__init__.py)
Traceback (most recent call last):
  File "/root/GPT_monitoring/webhook_server.py", line 1, in <module>
    from future import annotations
ImportError: cannot import name 'annotations' from 'future' (/root/GPT_monitoring/.venv/lib/python3.12/site-packages/future/__init__.py)
Traceback (most recent call last):
  File "/root/GPT_monitoring/webhook_server.py", line 1, in <module>
    from future import annotations
ImportError: cannot import name 'annotations' from 'future' (/root/GPT_monitoring/.venv/lib/python3.12/site-packages/future/__init__.py)
Traceback (most recent call last):
  File "/root/GPT_monitoring/webhook_server.py", line 1, in <module>
    from future import annotations
ImportError: cannot import name 'annotations' from 'future' (/root/GPT_monitoring/.venv/lib/python3.12/site-packages/future/__init__.py)
Traceback (most recent call last):
  File "/root/GPT_monitoring/webhook_server.py", line 1, in <module>
    from future import annotations
ImportError: cannot import name 'annotations' from 'future' (/root/GPT_monitoring/.venv/lib/python3.12/site-packages/future/__init__.py)
Traceback (most recent call last):
  File "/root/GPT_monitoring/webhook_server.py", line 1, in <module>
    from future import annotations
ImportError: cannot import name 'annotations' from 'future' (/root/GPT_monitoring/.venv/lib/python3.12/site-packages/future/__init__.py)
Traceback (most recent call last):
  File "/root/GPT_monitoring/webhook_server.py", line 1, in <module>
    from future import annotations
ImportError: cannot import name 'annotations' from 'future' (/root/GPT_monitoring/.venv/lib/python3.12/site-packages/future/__init__.py)
Traceback (most recent call last):
  File "/root/GPT_monitoring/webhook_server.py", line 1, in <module>
    from future import annotations
ImportError: cannot import name 'annotations' from 'future' (/root/GPT_monitoring/.venv/lib/python3.12/site-packages/future/__init__.py)
Traceback (most recent call last):
  File "/root/GPT_monitoring/webhook_server.py", line 1, in <module>
    from future import annotations
ImportError: cannot import name 'annotations' from 'future' (/root/GPT_monitoring/.venv/lib/python3.12/site-packages/future/__init__.py)
Traceback (most recent call last):
  File "/root/GPT_monitoring/webhook_server.py", line 1, in <module>
    from future import annotations
ImportError: cannot import name 'annotations' from 'future' (/root/GPT_monitoring/.venv/lib/python3.12/site-packages/future/__init__.py)
Traceback (most recent call last):
  File "/root/GPT_monitoring/webhook_server.py", line 1, in <module>
    from future import annotations
ImportError: cannot import name 'annotations' from 'future' (/root/GPT_monitoring/.venv/lib/python3.12/site-packages/future/__init__.py)
Traceback (most recent call last):
  File "/root/GPT_monitoring/webhook_server.py", line 1, in <module>
    from future import annotations
ImportError: cannot import name 'annotations' from 'future' (/root/GPT_monitoring/.venv/lib/python3.12/site-packages/future/__init__.py)
Traceback (most recent call last):
  File "/root/GPT_monitoring/webhook_server.py", line 1, in <module>
    from future import annotations
ImportError: cannot import name 'annotations' from 'future' (/root/GPT_monitoring/.venv/lib/python3.12/site-packages/future/__init__.py)
Traceback (most recent call last):
  File "/root/GPT_monitoring/webhook_server.py", line 1, in <module>
    from future import annotations
ImportError: cannot import name 'annotations' from 'future' (/root/GPT_monitoring/.venv/lib/python3.12/site-packages/future/__init__.py)
Traceback (most recent call last):
  File "/root/GPT_monitoring/webhook_server.py", line 1, in <module>
    from future import annotations
ImportError: cannot import name 'annotations' from 'future' (/root/GPT_monitoring/.venv/lib/python3.12/site-packages/future/__init__.py)
Traceback (most recent call last):
  File "/root/GPT_monitoring/webhook_server.py", line 1, in <module>
    from future import annotations
ImportError: cannot import name 'annotations' from 'future' (/root/GPT_monitoring/.venv/lib/python3.12/site-packages/future/__init__.py)
Traceback (most recent call last):
  File "/root/GPT_monitoring/webhook_server.py", line 1, in <module>
    from future import annotations
ImportError: cannot import name 'annotations' from 'future' (/root/GPT_monitoring/.venv/lib/python3.12/site-packages/future/__init__.py)
Traceback (most recent call last):
  File "/root/GPT_monitoring/webhook_server.py", line 1, in <module>
    from future import annotations
ImportError: cannot import name 'annotations' from 'future' (/root/GPT_monitoring/.venv/lib/python3.12/site-packages/future/__init__.py)
Traceback (most recent call last):
  File "/root/GPT_monitoring/webhook_server.py", line 1, in <module>
    from future import annotations
ImportError: cannot import name 'annotations' from 'future' (/root/GPT_monitoring/.venv/lib/python3.12/site-packages/future/__init__.py)
Traceback (most recent call last):
  File "/root/GPT_monitoring/webhook_server.py", line 1, in <module>
    from future import annotations
ImportError: cannot import name 'annotations' from 'future' (/root/GPT_monitoring/.venv/lib/python3.12/site-packages/future/__init__.py)
Traceback (most recent call last):
  File "/root/GPT_monitoring/webhook_server.py", line 1, in <module>
    from future import annotations
ImportError: cannot import name 'annotations' from 'future' (/root/GPT_monitoring/.venv/lib/python3.12/site-packages/future/__init__.py)
Traceback (most recent call last):
  File "/root/GPT_monitoring/webhook_server.py", line 1, in <module>
    from future import annotations
ImportError: cannot import name 'annotations' from 'future' (/root/GPT_monitoring/.venv/lib/python3.12/site-packages/future/__init__.py)
Traceback (most recent call last):
  File "/root/GPT_monitoring/webhook_server.py", line 1, in <module>
    from future import annotations
ImportError: cannot import name 'annotations' from 'future' (/root/GPT_monitoring/.venv/lib/python3.12/site-packages/future/__init__.py)
Traceback (most recent call last):
  File "/root/GPT_monitoring/webhook_server.py", line 1, in <module>
    from future import annotations
ImportError: cannot import name 'annotations' from 'future' (/root/GPT_monitoring/.venv/lib/python3.12/site-packages/future/__init__.py)
Traceback (most recent call last):
  File "/root/GPT_monitoring/webhook_server.py", line 1, in <module>
    from future import annotations
ImportError: cannot import name 'annotations' from 'future' (/root/GPT_monitoring/.venv/lib/python3.12/site-packages/future/__init__.py)
Traceback (most recent call last):
  File "/root/GPT_monitoring/webhook_server.py", line 1, in <module>
    from future import annotations
ImportError: cannot import name 'annotations' from 'future' (/root/GPT_monitoring/.venv/lib/python3.12/site-packages/future/__init__.py)
Traceback (most recent call last):
  File "/root/GPT_monitoring/webhook_server.py", line 1, in <module>
    from future import annotations
ImportError: cannot import name 'annotations' from 'future' (/root/GPT_monitoring/.venv/lib/python3.12/site-packages/future/__init__.py)
Traceback (most recent call last):
  File "/root/GPT_monitoring/webhook_server.py", line 1, in <module>
    from future import annotations
ImportError: cannot import name 'annotations' from 'future' (/root/GPT_monitoring/.venv/lib/python3.12/site-packages/future/__init__.py)
Traceback (most recent call last):
  File "/root/GPT_monitoring/webhook_server.py", line 1, in <module>
    from future import annotations
ImportError: cannot import name 'annotations' from 'future' (/root/GPT_monitoring/.venv/lib/python3.12/site-packages/future/__init__.py)
Traceback (most recent call last):
  File "/root/GPT_monitoring/webhook_server.py", line 1, in <module>
    from future import annotations
ImportError: cannot import name 'annotations' from 'future' (/root/GPT_monitoring/.venv/lib/python3.12/site-packages/future/__init__.py)
Traceback (most recent call last):
  File "/root/GPT_monitoring/webhook_server.py", line 1, in <module>
    from future import annotations
ImportError: cannot import name 'annotations' from 'future' (/root/GPT_monitoring/.venv/lib/python3.12/site-packages/future/__init__.py)
Traceback (most recent call last):
  File "/root/GPT_monitoring/webhook_server.py", line 1, in <module>
    from future import annotations
ImportError: cannot import name 'annotations' from 'future' (/root/GPT_monitoring/.venv/lib/python3.12/site-packages/future/__init__.py)
Traceback (most recent call last):
  File "/root/GPT_monitoring/webhook_server.py", line 1, in <module>
    from future import annotations
ImportError: cannot import name 'annotations' from 'future' (/root/GPT_monitoring/.venv/lib/python3.12/site-packages/future/__init__.py)
Traceback (most recent call last):
  File "/root/GPT_monitoring/webhook_server.py", line 1, in <module>
    from future import annotations
ImportError: cannot import name 'annotations' from 'future' (/root/GPT_monitoring/.venv/lib/python3.12/site-packages/future/__init__.py)
Traceback (most recent call last):
  File "/root/GPT_monitoring/webhook_server.py", line 1, in <module>
    from future import annotations
ImportError: cannot import name 'annotations' from 'future' (/root/GPT_monitoring/.venv/lib/python3.12/site-packages/future/__init__.py)
Traceback (most recent call last):
  File "/root/GPT_monitoring/webhook_server.py", line 1, in <module>
    from future import annotations
ImportError: cannot import name 'annotations' from 'future' (/root/GPT_monitoring/.venv/lib/python3.12/site-packages/future/__init__.py)
Traceback (most recent call last):
  File "/root/GPT_monitoring/webhook_server.py", line 1, in <module>
    from future import annotations
ImportError: cannot import name 'annotations' from 'future' (/root/GPT_monitoring/.venv/lib/python3.12/site-packages/future/__init__.py)
Traceback (most recent call last):
  File "/root/GPT_monitoring/webhook_server.py", line 1, in <module>
    from future import annotations
ImportError: cannot import name 'annotations' from 'future' (/root/GPT_monitoring/.venv/lib/python3.12/site-packages/future/__init__.py)
Traceback (most recent call last):
  File "/root/GPT_monitoring/webhook_server.py", line 1, in <module>
    from future import annotations
ImportError: cannot import name 'annotations' from 'future' (/root/GPT_monitoring/.venv/lib/python3.12/site-packages/future/__init__.py)
Traceback (most recent call last):
  File "/root/GPT_monitoring/webhook_server.py", line 1, in <module>
    from future import annotations
ImportError: cannot import name 'annotations' from 'future' (/root/GPT_monitoring/.venv/lib/python3.12/site-packages/future/__init__.py)
Traceback (most recent call last):
  File "/root/GPT_monitoring/webhook_server.py", line 1, in <module>
    from future import annotations
ImportError: cannot import name 'annotations' from 'future' (/root/GPT_monitoring/.venv/lib/python3.12/site-packages/future/__init__.py)
Traceback (most recent call last):
  File "/root/GPT_monitoring/webhook_server.py", line 1, in <module>
    from future import annotations
ImportError: cannot import name 'annotations' from 'future' (/root/GPT_monitoring/.venv/lib/python3.12/site-packages/future/__init__.py)
Traceback (most recent call last):
  File "/root/GPT_monitoring/webhook_server.py", line 1, in <module>
    from future import annotations
ImportError: cannot import name 'annotations' from 'future' (/root/GPT_monitoring/.venv/lib/python3.12/site-packages/future/__init__.py)
Traceback (most recent call last):
  File "/root/GPT_monitoring/webhook_server.py", line 1, in <module>
    from future import annotations
ImportError: cannot import name 'annotations' from 'future' (/root/GPT_monitoring/.venv/lib/python3.12/site-packages/future/__init__.py)
Traceback (most recent call last):
  File "/root/GPT_monitoring/webhook_server.py", line 1, in <module>
    from future import annotations
ImportError: cannot import name 'annotations' from 'future' (/root/GPT_monitoring/.venv/lib/python3.12/site-packages/future/__init__.py)
Traceback (most recent call last):
  File "/root/GPT_monitoring/webhook_server.py", line 1, in <module>
    from future import annotations
ImportError: cannot import name 'annotations' from 'future' (/root/GPT_monitoring/.venv/lib/python3.12/site-packages/future/__init__.py)
Traceback (most recent call last):
  File "/root/GPT_monitoring/webhook_server.py", line 1, in <module>
    from future import annotations
ImportError: cannot import name 'annotations' from 'future' (/root/GPT_monitoring/.venv/lib/python3.12/site-packages/future/__init__.py)
Traceback (most recent call last):
  File "/root/GPT_monitoring/webhook_server.py", line 1, in <module>
    from future import annotations
ImportError: cannot import name 'annotations' from 'future' (/root/GPT_monitoring/.venv/lib/python3.12/site-packages/future/__init__.py)
Traceback (most recent call last):
  File "/root/GPT_monitoring/webhook_server.py", line 1, in <module>
    from future import annotations
ImportError: cannot import name 'annotations' from 'future' (/root/GPT_monitoring/.venv/lib/python3.12/site-packages/future/__init__.py)
2025-10-22 21:50:07,385 | INFO | werkzeug | [31m[1mWARNING: This is a development server. Do not use it in a production deployment. Use a production WSGI server instead.[0m
 * Running on all addresses (0.0.0.0)
 * Running on http://127.0.0.1:5000
 * Running on http://195.14.122.180:5000
2025-10-22 21:50:07,386 | INFO | werkzeug | [33mPress CTRL+C to quit[0m
2025-10-22 21:50:25,221 | INFO | werkzeug | [31m[1mWARNING: This is a development server. Do not use it in a production deployment. Use a production WSGI server instead.[0m
 * Running on all addresses (0.0.0.0)
 * Running on http://127.0.0.1:5000
 * Running on http://195.14.122.180:5000
2025-10-22 21:50:25,222 | INFO | werkzeug | [33mPress CTRL+C to quit[0m
